Workbook

Sheet 30-07
B1: Qtde. Total chamados Status | H1: Qtde. Total chamados por categoria | R1: Mês/Ano | S1: jul/2026
H2: Status | I2: PENDENTE | R2: Data de abertura | S2: (Tudo)
B4: #VALUE! | I4: Rótulos de Coluna | R4: Rótulos de Linha | S4: Contagem de Número do Chamado
I5: 2025 | J5: 2026 | K5: - | R5: Emilly Maria | S5: 20
R6: Fabiana Lisboa | S6: 12
R7: Pamela de Sá | S7: 24
R8: Stephany Lima | S8: 37
H9: Contagem de Número de protocolo | I9: 11 | J9: 84 | K9: 95 | R9: Vanessa Araujo | S9: 4
R10: Total Geral | S10: 97
B17: Qtde. Chamados por categoria x responsável
B18: Status | C18: PENDENTE
B19: Data de abertura | C19: (Vários itens)
B21: Rótulos de Linha | C21: Contagem Chamado
B22: Emilly Maria | C22: 13
B23: Fabiana Lisboa | C23: 10
B24: Pamela de Sá | C24: 23
B25: Stephany Lima | C25: 32
B26: Vanessa Araujo | C26: 6
B27: Total Geral | C27: 84
D45: Amanda verificar

Sheet Dashboard
B2: Painel de Acompanhamento
B4: Indicadores Gerais | N4: Situação Últimos 30 Dias
B5: TOTAL DE CHAMADOS | D5: CHAMADOS ABERTOS | F5: CHAMADOS ENCERRADOS | H5: ATENDIDOS ÚLT. 7 DIAS | J5: REABERTOS | N5: ABERTOS | P5: ENCERRADOS | R5: AINDA ABERTOS
B6: =COUNTA('Compilado chamados'!D5:D1048576) -> 409 | D6: =COUNTIF('Compilado chamados'!Y5:Y1048576,"Aberto") -> 155 | F6: =COUNTIF('Compilado chamados'!Y5:Y1048576,"Encerrado") -> 254 | H6: =COUNTIFS('Compilado chamados'!Y5:Y1048576,"Encerrado",'Compilado chamados'!X5:X1048576,">="&TODAY()-7,'Compilado chamados'!X5:X1048576,"<="&TODAY()) -> 27 | J6: =COUNTIF('Compilado chamados'!L:L,"REABERTO") -> 0 | N6: =COUNTIFS('Compilado chamados'!O5:O1048576,">="&TODAY()-30,'Compilado chamados'!O5:O1048576,"<="&TODAY()) -> 35 | P6: =COUNTIFS('Compilado chamados'!Y5:Y1048576,"Encerrado",'Compilado chamados'!O5:O1048576,">="&TODAY()-30,'Compilado chamados'!O5:O1048576,"<="&TODAY()) -> 19 | R6: =COUNTIFS('Compilado chamados'!Y5:Y1048576,"Aberto",'Compilado chamados'!O5:O1048576,">="&TODAY()-30,'Compilado chamados'!O5:O1048576,"<="&TODAY()) -> 16
B9: Chamados Atendidos por Mês (Encerrados) | N9: Chamados por Classificação
B10: Mês | C10: Atendidos | O10: Atendidos | P10: Em Aberto | Q10: Abertos Últ. 30d
B11: Mar/2026 | C11: =COUNTIFS('Compilado chamados'!$Y$5:$Y$1048576,"Encerrado",'Compilado chamados'!$X$5:$X$1048576,">="&DATE(2026,3,1),'Compilado chamados'!$X$5:$X$1048576,"<"&EDATE(DATE(2026,3,1),1)) -> 1 | N11: Cancelamento e Reemissão de Nota Fiscal | O11: =COUNTIFS('Compilado chamados'!C:C,N11,'Compilado chamados'!Y:Y,"Encerrado") -> 98 | P11: =COUNTIFS('Compilado chamados'!C:C,N11,'Compilado chamados'!Y:Y,"Aberto") -> 56 | Q11: =COUNTIFS( 'Compilado chamados'!C:C,N11, 'Compilado chamados'!Y:Y,"Aberto", 'Compilado chamados'!O:O,">="&TODAY()-30, 'Compilado chamados'!O:O,"<"&TODAY()+1 ) -> 6
B12: Abr/2026 | C12: =COUNTIFS('Compilado chamados'!$Y$5:$Y$1048576,"Encerrado",'Compilado chamados'!$X$5:$X$1048576,">="&DATE(2026,4,1),'Compilado chamados'!$X$5:$X$1048576,"<"&EDATE(DATE(2026,4,1),1)) -> 1 | N12: Cobrança e Contestação | O12: =COUNTIFS('Compilado chamados'!C:C,N12,'Compilado chamados'!Y:Y,"Encerrado") -> 38 | P12: =COUNTIFS('Compilado chamados'!C:C,N12,'Compilado chamados'!Y:Y,"Aberto") -> 41 | Q12: =COUNTIFS( 'Compilado chamados'!C:C,N12, 'Compilado chamados'!Y:Y,"Aberto", 'Compilado chamados'!O:O,">="&TODAY()-30, 'Compilado chamados'!O:O,"<"&TODAY()+1 ) -> 2
B13: Mai/2026 | C13: =COUNTIFS('Compilado chamados'!$Y$5:$Y$1048576,"Encerrado",'Compilado chamados'!$X$5:$X$1048576,">="&DATE(2026,5,1),'Compilado chamados'!$X$5:$X$1048576,"<"&EDATE(DATE(2026,5,1),1)) -> 3 | N13: Pagamentos, Boletos e Recebimentos | O13: =COUNTIFS('Compilado chamados'!C:C,N13,'Compilado chamados'!Y:Y,"Encerrado") -> 50 | P13: =COUNTIFS('Compilado chamados'!C:C,N13,'Compilado chamados'!Y:Y,"Aberto") -> 22 | Q13: =COUNTIFS( 'Compilado chamados'!C:C,N13, 'Compilado chamados'!Y:Y,"Aberto", 'Compilado chamados'!O:O,">="&TODAY()-30, 'Compilado chamados'!O:O,"<"&TODAY()+1 ) -> 3
B14: Jun/2026 | C14: =COUNTIFS('Compilado chamados'!$Y$5:$Y$1048576,"Encerrado",'Compilado chamados'!$X$5:$X$1048576,">="&DATE(2026,6,1),'Compilado chamados'!$X$5:$X$1048576,"<"&EDATE(DATE(2026,6,1),1)) -> 0 | N14: Contratos, Comercial e Cadastro | O14: =COUNTIFS('Compilado chamados'!C:C,N14,'Compilado chamados'!Y:Y,"Encerrado") -> 43 | P14: =COUNTIFS('Compilado chamados'!C:C,N14,'Compilado chamados'!Y:Y,"Aberto") -> 15 | Q14: =COUNTIFS( 'Compilado chamados'!C:C,N14, 'Compilado chamados'!Y:Y,"Aberto", 'Compilado chamados'!O:O,">="&TODAY()-30, 'Compilado chamados'!O:O,"<"&TODAY()+1 ) -> 2
B15: Jul/2026 | C15: =COUNTIFS('Compilado chamados'!$Y$5:$Y$1048576,"Encerrado",'Compilado chamados'!$X$5:$X$1048576,">="&DATE(2026,7,1),'Compilado chamados'!$X$5:$X$1048576,"<"&EDATE(DATE(2026,7,1),1)) -> 74 | N15: Atendimento Administrativo e Suporte | O15: =COUNTIFS('Compilado chamados'!C:C,N15,'Compilado chamados'!Y:Y,"Encerrado") -> 18 | P15: =COUNTIFS('Compilado chamados'!C:C,N15,'Compilado chamados'!Y:Y,"Aberto") -> 11 | Q15: =COUNTIFS( 'Compilado chamados'!C:C,N15, 'Compilado chamados'!Y:Y,"Aberto", 'Compilado chamados'!O:O,">="&TODAY()-30, 'Compilado chamados'!O:O,"<"&TODAY()+1 ) -> 2
B16: Ago/2026 | C16: =COUNTIFS('Compilado chamados'!$Y$5:$Y$1048576,"Encerrado",'Compilado chamados'!$X$5:$X$1048576,">="&DATE(2026,8,1),'Compilado chamados'!$X$5:$X$1048576,"<"&EDATE(DATE(2026,8,1),1)) -> 96 | N16: Faturamento e Obrigações Fiscais | O16: =COUNTIFS('Compilado chamados'!C:C,N16,'Compilado chamados'!Y:Y,"Encerrado") -> 7 | P16: =COUNTIFS('Compilado chamados'!C:C,N16,'Compilado chamados'!Y:Y,"Aberto") -> 9 | Q16: =COUNTIFS( 'Compilado chamados'!C:C,N16, 'Compilado chamados'!Y:Y,"Aberto", 'Compilado chamados'!O:O,">="&TODAY()-30, 'Compilado chamados'!O:O,"<"&TODAY()+1 ) -> 1
B17: Set/2026 | C17: =COUNTIFS('Compilado chamados'!$Y$5:$Y$1048576,"Encerrado",'Compilado chamados'!$X$5:$X$1048576,">="&DATE(2026,9,1),'Compilado chamados'!$X$5:$X$1048576,"<"&EDATE(DATE(2026,9,1),1)) -> 78
B20: Chamados por Responsável
B21: Classificação | C21: Atendidos | D21: Encerrado Últ. 7 Dias | E21: Em Andamento | F21: Em Aberto | G21: Prioridade
B22: Vanessa Araujo | C22: =COUNTIFS('Compilado chamados'!B:B,Dashboard!B22,'Compilado chamados'!Y:Y,"Encerrado") -> 8 | D22: =COUNTIFS( 'Compilado chamados'!B:B,Dashboard!B22, 'Compilado chamados'!Y:Y,"Encerrado", 'Compilado chamados'!X:X,">="&TODAY()-7, 'Compilado chamados'!X:X,"<"&TODAY()+1 ) -> 1 | E22: =COUNTIFS('Compilado chamados'!B:B,Dashboard!B22,'Compilado chamados'!L:L,"EM ANDAMENTO") -> 0 | F22: =COUNTIFS('Compilado chamados'!B:B,Dashboard!B22,'Compilado chamados'!Y:Y,"Aberto") -> 0 | G22: =COUNTIFS('Compilado chamados'!B:B,Dashboard!B22,'Compilado chamados'!M:M,"Alta") -> 0
B23: Stephany Lima | C23: =COUNTIFS('Compilado chamados'!B:B,Dashboard!B23,'Compilado chamados'!Y:Y,"Encerrado") -> 78 | D23: =COUNTIFS( 'Compilado chamados'!B:B,Dashboard!B23, 'Compilado chamados'!Y:Y,"Encerrado", 'Compilado chamados'!X:X,">="&TODAY()-7, 'Compilado chamados'!X:X,"<"&TODAY()+1 ) -> 7 | E23: =COUNTIFS('Compilado chamados'!B:B,Dashboard!B23,'Compilado chamados'!L:L,"EM ANDAMENTO") -> 11 | F23: =COUNTIFS('Compilado chamados'!B:B,Dashboard!B23,'Compilado chamados'!Y:Y,"Aberto") -> 58 | G23: =COUNTIFS('Compilado chamados'!B:B,Dashboard!B23,'Compilado chamados'!M:M,"Alta") -> 18
B24: Pamela de Sá | C24: =COUNTIFS('Compilado chamados'!B:B,Dashboard!B24,'Compilado chamados'!Y:Y,"Encerrado") -> 28 | D24: =COUNTIFS( 'Compilado chamados'!B:B,Dashboard!B24, 'Compilado chamados'!Y:Y,"Encerrado", 'Compilado chamados'!X:X,">="&TODAY()-7, 'Compilado chamados'!X:X,"<"&TODAY()+1 ) -> 1 | E24: =COUNTIFS('Compilado chamados'!B:B,Dashboard!B24,'Compilado chamados'!L:L,"EM ANDAMENTO") -> 8 | F24: =COUNTIFS('Compilado chamados'!B:B,Dashboard!B24,'Compilado chamados'!Y:Y,"Aberto") -> 35 | G24: =COUNTIFS('Compilado chamados'!B:B,Dashboard!B24,'Compilado chamados'!M:M,"Alta") -> 7
B25: Emilly Maria | C25: =COUNTIFS('Compilado chamados'!B:B,Dashboard!B25,'Compilado chamados'!Y:Y,"Encerrado") -> 80 | D25: =COUNTIFS( 'Compilado chamados'!B:B,Dashboard!B25, 'Compilado chamados'!Y:Y,"Encerrado", 'Compilado chamados'!X:X,">="&TODAY()-7, 'Compilado chamados'!X:X,"<"&TODAY()+1 ) -> 8 | E25: =COUNTIFS('Compilado chamados'!B:B,Dashboard!B25,'Compilado chamados'!L:L,"EM ANDAMENTO") -> 5 | F25: =COUNTIFS('Compilado chamados'!B:B,Dashboard!B25,'Compilado chamados'!Y:Y,"Aberto") -> 37 | G25: =COUNTIFS('Compilado chamados'!B:B,Dashboard!B25,'Compilado chamados'!M:M,"Alta") -> 14
B26: Amanda Silva | C26: =COUNTIFS('Compilado chamados'!B:B,Dashboard!B26,'Compilado chamados'!Y:Y,"Encerrado") -> 40 | D26: =COUNTIFS( 'Compilado chamados'!B:B,Dashboard!B26, 'Compilado chamados'!Y:Y,"Encerrado", 'Compilado chamados'!X:X,">="&TODAY()-7, 'Compilado chamados'!X:X,"<"&TODAY()+1 ) -> 10 | E26: =COUNTIFS('Compilado chamados'!B:B,Dashboard!B26,'Compilado chamados'!L:L,"EM ANDAMENTO") -> 4 | F26: =COUNTIFS('Compilado chamados'!B:B,Dashboard!B26,'Compilado chamados'!Y:Y,"Aberto") -> 25 | G26: =COUNTIFS('Compilado chamados'!B:B,Dashboard!B26,'Compilado chamados'!M:M,"Alta") -> 6
B29: Atendidos nos Últimos 7 Dias
B30: Data | C30: Dia da Semana | D30: Atendidos
B31: =TODAY()-7 -> 46283 | C31: =TEXT(B31,"ddd") -> sex | D31: =COUNTIFS('Compilado chamados'!$Y$5:$Y$1048576,"Encerrado",'Compilado chamados'!$X$5:$X$1048576,B31) -> 4 | N31: Origem Chamados
B32: =TODAY()-6 -> 46284 | C32: =TEXT(B32,"ddd") -> sáb | D32: =COUNTIFS('Compilado chamados'!$Y$5:$Y$1048576,"Encerrado",'Compilado chamados'!$X$5:$X$1048576,B32) -> 0 | N32: Interno | O32: =COUNTIF('Compilado chamados'!AB:AB,N32) -> 195
B33: =TODAY()-5 -> 46285 | C33: =TEXT(B33,"ddd") -> dom | D33: =COUNTIFS('Compilado chamados'!$Y$5:$Y$1048576,"Encerrado",'Compilado chamados'!$X$5:$X$1048576,B33) -> 0 | N33: Externo | O33: =COUNTIF('Compilado chamados'!AB:AB,N33) -> 214
B34: =TODAY()-4 -> 46286 | C34: =TEXT(B34,"ddd") -> seg | D34: =COUNTIFS('Compilado chamados'!$Y$5:$Y$1048576,"Encerrado",'Compilado chamados'!$X$5:$X$1048576,B34) -> 2
B35: =TODAY()-3 -> 46287 | C35: =TEXT(B35,"ddd") -> ter | D35: =COUNTIFS('Compilado chamados'!$Y$5:$Y$1048576,"Encerrado",'Compilado chamados'!$X$5:$X$1048576,B35) -> 10
B36: =TODAY()-2 -> 46288 | C36: =TEXT(B36,"ddd") -> qua | D36: =COUNTIFS('Compilado chamados'!$Y$5:$Y$1048576,"Encerrado",'Compilado chamados'!$X$5:$X$1048576,B36) -> 5
B37: =TODAY()-1 -> 46289 | C37: =TEXT(B37,"ddd") -> qui | D37: =COUNTIFS('Compilado chamados'!$Y$5:$Y$1048576,"Encerrado",'Compilado chamados'!$X$5:$X$1048576,B37) -> 5
B38: Total 7 dias | D38: =SUM(D31:D37) -> 26

Sheet Resumo p. Respónsável
A1: Chamados em aberto por Categoria/Responsável | D1: Atendimento por Dia/Responsável
A3: Status | B3: (Vários itens) | D3: Status | E3: FINALIZADO
A5: Rótulos de Linha | B5: Contagem de Número do Chamado | D5: Contagem de Número do Chamado | E5: Rótulos de Coluna
A6: Emilly Maria | B6: 35 | E6: <09/01/2026 | F6: jan | G6: mar | H6: abr | I6: mai | J6: jul | AA6: jul Total | AB6: ago | AT6: ago Total | AU6: set | BK6: set Total | BL6: Total Geral
A7: Atendimento Administrativo e Suporte | B7: 3 | J7: 10/jul | K7: 11/jul | L7: 13/jul | M7: 14/jul | N7: 15/jul | O7: 16/jul | P7: 17/jul | Q7: 20/jul | R7: 21/jul | S7: 22/jul | T7: 23/jul | U7: 24/jul | V7: 27/jul | W7: 28/jul | X7: 29/jul | Y7: 30/jul | Z7: 31/jul | AB7: 03/ago | AC7: 04/ago | AD7: 05/ago | AE7: 06/ago | AF7: 07/ago | AG7: 08/ago | AH7: 10/ago | AI7: 11/ago | AJ7: 12/ago | AK7: 13/ago | AL7: 14/ago | AM7: 18/ago | AN7: 20/ago | AO7: 24/ago | AP7: 25/ago | AQ7: 26/ago | AR7: 27/ago | AS7: 28/ago | AU7: 02/set | AV7: 03/set | AW7: 04/set | AX7: 08/set | AY7: 09/set | AZ7: 10/set | BA7: 11/set | BB7: 14/set | BC7: 15/set | BD7: 16/set | BE7: 17/set | BF7: 18/set | BG7: 21/set | BH7: 22/set | BI7: 23/set | BJ7: 24/set
A8: Cancelamento e Reemissão de Nota Fiscal | B8: 13 | D8: Rótulos de Linha
A9: Cobrança e Contestação | B9: 8 | D9: Emilly Maria | G9: 1 | I9: 1 | M9: 3 | N9: 1 | O9: 2 | P9: 2 | Q9: 1 | S9: 1 | T9: 2 | X9: 1 | Y9: 6 | Z9: 4 | AA9: 23 | AC9: 1 | AD9: 1 | AE9: 9 | AF9: 3 | AH9: 3 | AI9: 5 | AK9: 1 | AL9: 5 | AM9: 1 | AO9: 3 | AP9: 2 | AQ9: 1 | AT9: 35 | AU9: 1 | AV9: 3 | AW9: 2 | AX9: 2 | AZ9: 1 | BA9: 2 | BC9: 1 | BH9: 5 | BI9: 1 | BJ9: 2 | BK9: 20 | BL9: 80
A10: Contratos, Comercial e Cadastro | B10: 3 | D10: Fabiana Lisboa | T10: 1 | U10: 2 | V10: 2 | W10: 1 | X10: 2 | Y10: 4 | AA10: 12 | AE10: 2 | AH10: 1 | AI10: 4 | AL10: 1 | AT10: 8 | BL10: 20
A11: Faturamento e Obrigações Fiscais | B11: 2 | D11: Pamela de Sá | P11: 1 | R11: 1 | S11: 1 | T11: 1 | W11: 2 | X11: 1 | Y11: 2 | Z11: 1 | AA11: 10 | AE11: 6 | AG11: 3 | AO11: 1 | AP11: 3 | AS11: 1 | AT11: 14 | AU11: 1 | BC11: 2 | BK11: 3 | BL11: 27
A12: Pagamentos, Boletos e Recebimentos | B12: 6 | D12: Stephany Lima | F12: 1 | H12: 1 | I12: 1 | J12: 1 | L12: 8 | M12: 2 | N12: 3 | Q12: 1 | R12: 1 | T12: 1 | U12: 1 | X12: 3 | Y12: 3 | Z12: 1 | AA12: 25 | AC12: 3 | AD12: 1 | AE12: 3 | AF12: 4 | AH12: 5 | AI12: 4 | AJ12: 5 | AN12: 2 | AQ12: 1 | AT12: 28 | AU12: 1 | AV12: 3 | AW12: 1 | AX12: 4 | AY12: 1 | BB12: 2 | BD12: 2 | BE12: 1 | BG12: 1 | BH12: 4 | BI12: 1 | BJ12: 1 | BK12: 22 | BL12: 78
A13: Pamela de Sá | B13: 36 | D13: Vanessa Araujo | K13: 1 | U13: 1 | W13: 1 | Y13: 1 | AA13: 4 | AH13: 1 | AI13: 1 | AQ13: 1 | AT13: 3 | BF13: 1 | BK13: 1 | BL13: 8
A14: Atendimento Administrativo e Suporte | B14: 4 | D14: Amanda Silva | E14: 1 | I14: 1 | AB14: 1 | AC14: 2 | AD14: 1 | AE14: 1 | AR14: 3 | AT14: 8 | AU14: 6 | AW14: 1 | AX14: 1 | BA14: 3 | BB14: 2 | BC14: 7 | BD14: 1 | BF14: 3 | BG14: 1 | BH14: 1 | BI14: 3 | BJ14: 1 | BK14: 30 | BL14: 40
A15: Cancelamento e Reemissão de Nota Fiscal | B15: 9 | D15: Total Geral | E15: 1 | F15: 1 | G15: 1 | H15: 1 | I15: 3 | J15: 1 | K15: 1 | L15: 8 | M15: 5 | N15: 4 | O15: 2 | P15: 3 | Q15: 2 | R15: 2 | S15: 2 | T15: 5 | U15: 4 | V15: 2 | W15: 4 | X15: 7 | Y15: 16 | Z15: 6 | AA15: 74 | AB15: 1 | AC15: 6 | AD15: 3 | AE15: 21 | AF15: 7 | AG15: 3 | AH15: 10 | AI15: 14 | AJ15: 5 | AK15: 1 | AL15: 6 | AM15: 1 | AN15: 2 | AO15: 4 | AP15: 5 | AQ15: 3 | AR15: 3 | AS15: 1 | AT15: 96 | AU15: 9 | AV15: 6 | AW15: 4 | AX15: 7 | AY15: 1 | AZ15: 1 | BA15: 5 | BB15: 4 | BC15: 10 | BD15: 3 | BE15: 1 | BF15: 4 | BG15: 2 | BH15: 10 | BI15: 5 | BJ15: 4 | BK15: 76 | BL15: 253
A16: Cobrança e Contestação | B16: 8
A17: Contratos, Comercial e Cadastro | B17: 6
A18: Faturamento e Obrigações Fiscais | B18: 4
A19: Pagamentos, Boletos e Recebimentos | B19: 4
A20: #N/D | B20: 1
A21: Stephany Lima | B21: 57
A22: Atendimento Administrativo e Suporte | B22: 1
A23: Cancelamento e Reemissão de Nota Fiscal | B23: 25
A24: Cobrança e Contestação | B24: 19
A25: Contratos, Comercial e Cadastro | B25: 5
A26: Faturamento e Obrigações Fiscais | B26: 2
A27: Pagamentos, Boletos e Recebimentos | B27: 5
... A35: Total Geral | B35: 148

Sheet D.As
E1: Solicitação | O1: Aprovação 1° nivel (Everton | R1: Aprovação 2° nivel (Tatebe) | U1: Aprovação 3° nivel (Calil)
B2: # | C2: Concluído | D2: Status | E2: Data | F2: Assunto e-mail | G2: Chamado | H2: D.A Comercial | I2: Natureza | J2: Contexto | K2: R$ | L2: Solicitante | M2: Ofensor | N2: Alçada necessária | O2: Data2 | P2: Aprovador | Q2: Obs | R2: Data4 | S2: Aprovador5 | T2: Obs6 | U2: Data7 | V2: Aprovador8 | W2: Obs9
B3: 1 | C3: FALSE | D3: =IF(AND(P3="OK",OR(S3="OK",S3="N/A"),OR(V3="OK",V3="N/A")),"Aprovado",IF(OR(P3="Reprovado",S3="Reprovado",V3="Reprovado"),"Reprovado","Pendente")) -> Aprovado | E3: 46231 | F3: Aprovação - Cancelamento de notas - MOITINHO AUTOMOVEIS LTDA 22.134.988/0001-14 - 20192438 | G3: =RIGHT(Tabela1[[#This Row],[Assunto e-mail]],8) -> 20192438 | H3: OK | I3: Cancelamento de NF | J3: Erro sistemico, o SF enviou ao billing tarifa diferente do contrato | K3: 36586.11 | L3: Fabiana | N3: =IF(K3<10000,"Everton",IF(K3<=50000,"Everton + Tatebe","Everton + Tatebe + Calil")) -> Everton + Tatebe | O3: 46232 | P3: OK | Q3: - | R3: 46259 | S3: OK | T3: =IF(K3<10000,"N/A","-") -> - | U3: =IF(K3<=50000,"N/A","") -> N/A | V3: =IF(K3<=50000,"N/A","") -> N/A | W3: =IF(K3<=50000,"N/A","-") -> N/A
B4: =B3+1 -> 2 | C4: FALSE | D4: =IF(AND(P4="OK",OR(S4="OK",S4="N/A"),OR(V4="OK",V4="N/A")),"Aprovado",IF(OR(P4="Reprovado",S4="Reprovado",V4="Reprovado"),"Reprovado","Pendente")) -> Aprovado | E4: 46232 | F4: Aprovação - Cancelamento de notas - OBJETIVO 1220 COMERCIO DE COSMETICO-30.318.916/0001-55 | 21602868 | G4: =RIGHT(Tabela1[[#This Row],[Assunto e-mail]],8) -> 21602868 | H4: OK | I4: Cancelamento de NF | J4: Estrategia comercial, cancelamento de 2 meses como desconto para o cliente | K4: 16214.4 | L4: Emilly | N4: =IF(K4<10000,"Everton",IF(K4<=50000,"Everton + Tatebe","Everton + Tatebe + Calil")) -> Everton + Tatebe | O4: 46233 | P4: OK | Q4: - | R4: 46244 | S4: OK | T4: =IF(K4<10000,"N/A","-") -> - | U4: =IF(K4<=50000,"N/A","") -> N/A | V4: =IF(K4<=50000,"N/A","") -> N/A | W4: =IF(K4<=50000,"N/A","-") -> N/A
B5: =B4+1 -> 3 | C5: FALSE | D5: =IF(AND(P5="OK",OR(S5="OK",S5="N/A"),OR(V5="OK",V5="N/A")),"Aprovado",IF(OR(P5="Reprovado",S5="Reprovado",V5="Reprovado"),"Reprovado","Pendente")) -> Aprovado | E5: 46232 | F5: Aprovação - Cancelamento de notas - ELO CONSULTORIA E SOLUCOES LTDA-54.709.015/0001-52 | 22101893 | G5: =RIGHT(Tabela1[[#This Row],[Assunto e-mail]],8) -> 22101893 | H5: OK | I5: Cancelamento de NF | J5: Contrato fora do padrão, cobrança de ISS padrão que não consta no contrato | K5: 8163.27 | L5: Emilly | N5: =IF(K5<10000,"Everton",IF(K5<=50000,"Everton + Tatebe","Everton + Tatebe + Calil")) -> Everton | O5: 46233 | P5: OK | Q5: - | R5: =IF(K5<10000,"N/A","") -> N/A | S5: =IF(K5<10000,"N/A","") -> N/A | T5: =IF(K5<10000,"N/A","-") -> N/A | U5: =IF(K5<=50000,"N/A","") -> N/A | V5: =IF(K5<=50000,"N/A","") -> N/A | W5: =IF(K5<=50000,"N/A","-") -> N/A
B6: =B5+1 -> 4 | C6: FALSE | D6: =IF(AND(P6="OK",OR(S6="OK",S6="N/A"),OR(V6="OK",V6="N/A")),"Aprovado",IF(OR(P6="Reprovado",S6="Reprovado",V6="Reprovado"),"Reprovado","Pendente")) -> Aprovado | E6: 46226 | F6: Aprovação - Cancelamento de notas - ELEVE DISTRIBUIDORA DE PRODUTOS NUTRICOSMETICOS LTDA-31.178.848/0001-39 |21338462 | G6: =RIGHT(Tabela1[[#This Row],[Assunto e-mail]],8) -> 21338462 | H6: OK | I6: Cancelamento de NF | J6: Cancelamento não tempestivo pela comercial na tentativa de reverter a decisão do cliente | K6: 178.42 | L6: Emilly | N6: =IF(K6<10000,"Everton",IF(K6<=50000,"Everton + Tatebe","Everton + Tatebe + Calil")) -> Everton | O6: 46233 | P6: OK | Q6: - | R6: =IF(K6<10000,"N/A","") -> N/A | S6: =IF(K6<10000,"N/A","") -> N/A | T6: =IF(K6<10000,"N/A","-") -> N/A | U6: =IF(K6<=50000,"N/A","") -> N/A | V6: =IF(K6<=50000,"N/A","") -> N/A | W6: =IF(K6<=50000,"N/A","-") -> N/A
B7: =B6+1 -> 5 | C7: FALSE | D7: =IF(AND(P7="OK",OR(S7="OK",S7="N/A"),OR(V7="OK",V7="N/A")),"Aprovado",IF(OR(P7="Reprovado",S7="Reprovado",V7="Reprovado"),"Reprovado","Pendente")) -> Aprovado | E7: 46231 | F7: Aprovação - Cancelamento de notas - DIRETIVA IMPORTACAO E DISTRIBUICAO- 52.833.913/0001-92 | 23024837 | G7: =RIGHT(Tabela1[[#This Row],[Assunto e-mail]],8) -> 23024837 | H7: OK | I7: Cancelamento de NF | J7: Erro sistemico, após o cancelamento do cliente houve cobrança do Min. Mensal | K7: 6428.58 | L7: Emilly | N7: =IF(K7<10000,"Everton",IF(K7<=50000,"Everton + Tatebe","Everton + Tatebe + Calil")) -> Everton | O7: 46233 | P7: OK | Q7: - | R7: =IF(K7<10000,"N/A","") -> N/A | S7: =IF(K7<10000,"N/A","") -> N/A | T7: =IF(K7<10000,"N/A","-") -> N/A | U7: =IF(K7<=50000,"N/A","") -> N/A | V7: =IF(K7<=50000,"N/A","") -> N/A | W7: =IF(K7<=50000,"N/A","-") -> N/A
B8: =B7+1 -> 6 | C8: FALSE | D8: =IF(AND(P8="OK",OR(S8="OK",S8="N/A"),OR(V8="OK",V8="N/A")),"Aprovado",IF(OR(P8="Reprovado",S8="Reprovado",V8="Reprovado"),"Reprovado","Pendente")) -> Pendente | E8: 46212 | F8: Aprovar o cancelamento de NFs | Cliente: WISHPAG LTDA - Chamado 18915650 | G8: =RIGHT(Tabela1[[#This Row],[Assunto e-mail]],8) -> 18915650 | H8: OK | I8: Cancelamento de NF | J8: Cancelamento não tempestivo pela comercial | K8: 160574.6 | L8: Vanessa | N8: =IF(K8<10000,"Everton",IF(K8<=50000,"Everton + Tatebe","Everton + Tatebe + Calil")) -> Everton + Tatebe + Calil | O8: 46216 | P8: OK | Q8: - | R8: 46226 | S8: OK | T8: =IF(K8<10000,"N/A","-") -> - | U8: =IF(K8<=50000,"N/A","") | V8: =IF(K8<=50000,"N/A","") | W8: =IF(K8<=50000,"N/A","-") -> -
B9: =B8+1 -> 7 | C9: FALSE | D9: =IF(AND(P9="OK",OR(S9="OK",S9="N/A"),OR(V9="OK",V9="N/A")),"Aprovado",IF(OR(P9="Reprovado",S9="Reprovado",V9="Reprovado"),"Reprovado","Pendente")) -> Aprovado | E9: 46233 | F9: Aprovação - Cancelamento de notas -ALFA AGENCIA DE VIAGENS LTDA - 07.141.168/0001-66 | 19467525 | G9: =RIGHT(Tabela1[[#This Row],[Assunto e-mail]],8) -> 19467525 | H9: N/A | I9: Cancelamento de NF | J9: Solicitação vencida, chamado de congeladomento do contrato após a emissão da NF | K9: 4636.73 | L9: Emilly | N9: =IF(K9<10000,"Everton",IF(K9<=50000,"Everton + Tatebe","Everton + Tatebe + Calil")) -> Everton | O9: 46233 | P9: OK | Q9: - | R9: =IF(K9<10000,"N/A","") -> N/A | S9: =IF(K9<10000,"N/A","") -> N/A | T9: =IF(K9<10000,"N/A","-") -> N/A | U9: =IF(K9<=50000,"N/A","") -> N/A | V9: =IF(K9<=50000,"N/A","") -> N/A | W9: =IF(K9<=50000,"N/A","-") -> N/A
B10: =B9+1 -> 8 | C10: FALSE | D10: =IF(AND(P10="OK",OR(S10="OK",S10="N/A"),OR(V10="OK",V10="N/A")),"Aprovado",IF(OR(P10="Reprovado",S10="Reprovado",V10="Reprovado"),"Reprovado","Pendente")) -> Pendente | E10: 46227 | F10: Aprovação - Cancelamento de notas - NEXTION PAY TECNOLOGIA LTDA 50.726.492/0001-75 - 21573732 | G10: =RIGHT(Tabela1[[#This Row],[Assunto e-mail]],8) -> 21573732 | H10: OK | I10: Cancelamento de NF | J10: Solicitação de cancelamento não efetivada, gerando emissão indevida de NFs para cliente identificado como fraude. | K10: 156876.52 | L10: Fabiana/ Vanessa | N10: =IF(K10<10000,"Everton",IF(K10<=50000,"Everton + Tatebe","Everton + Tatebe + Calil")) -> Everton + Tatebe + Calil | O10: 46241 | P10: OK | Q10: Sob revisão do texto | R10: =IF(K10<10000,"N/A","") | S10: =IF(K10<10000,"N/A","") | T10: =IF(K10<10000,"N/A","-") -> - | U10: =IF(K10<=50000,"N/A","") | V10: =IF(K10<=50000,"N/A","") | W10: =IF(K10<=50000,"N/A","-") -> -
B11: =B10+1 -> 9 | C11: FALSE | D11: =IF(AND(P11="OK",OR(S11="OK",S11="N/A"),OR(V11="OK",V11="N/A")),"Aprovado",IF(OR(P11="Reprovado",S11="Reprovado",V11="Reprovado"),"Reprovado","Pendente")) -> Aprovado | E11: 46227 | F11: Aprovação - Cancelamento de notas - VOAI TECH LTDA-17.891.555/0001-73 | 21029459 | G11: =RIGHT(Tabela1[[#This Row],[Assunto e-mail]],8) -> 21029459 | H11: OK | I11: Cancelamento de NF | J11: Cadastro incorreto, o SF envio para o Billing produtos que não estão em contrato | K11: 1840.8 | L11: Emilly | N11: =IF(K11<10000,"Everton",IF(K11<=50000,"Everton + Tatebe","Everton + Tatebe + Calil")) -> Everton | O11: 46233 | P11: OK | Q11: - | R11: =IF(K11<10000,"N/A","") -> N/A | S11: =IF(K11<10000,"N/A","") -> N/A | T11: =IF(K11<10000,"N/A","-") -> N/A | U11: =IF(K11<=50000,"N/A","") -> N/A | V11: =IF(K11<=50000,"N/A","") -> N/A | W11: =IF(K11<=50000,"N/A","-") -> N/A
B12: =B11+1 -> 10 | C12: FALSE | D12: =IF(AND(P12="OK",OR(S12="OK",S12="N/A"),OR(V12="OK",V12="N/A")),"Aprovado",IF(OR(P12="Reprovado",S12="Reprovado",V12="Reprovado"),"Reprovado","Pendente")) -> Aprovado | E12: 46217 | F12: Aprovação - Cancelamento de notas fiscais - FAROL COMUNICACAO E SERVICOS DE INFORMATICA LTDA 21.011.165/0001-39 - 21124852 | G12: =RIGHT(Tabela1[[#This Row],[Assunto e-mail]],8) -> 21124852 | H12: OK | I12: Cancelamento de NF | J12: Cancelamento não tempestivo pela comercial na tentativa de reverter a decisão do cliente | K12: =3*973.14+174.54 -> 3093.96 | L12: Stephany | N12: =IF(K12<10000,"Everton",IF(K12<=50000,"Everton + Tatebe","Everton + Tatebe + Calil")) -> Everton | O12: 46233 | P12: OK | Q12: - | R12: =IF(K12<10000,"N/A","") -> N/A | S12: =IF(K12<10000,"N/A","") -> N/A | T12: =IF(K12<10000,"N/A","-") -> N/A | U12: =IF(K12<=50000,"N/A","") -> N/A | V12: =IF(K12<=50000,"N/A","") -> N/A | W12: =IF(K12<=50000,"N/A","-") -> N/A
B13: =B12+1 -> 11 | C13: FALSE | D13: =IF(AND(P13="OK",OR(S13="OK",S13="N/A"),OR(V13="OK",V13="N/A")),"Aprovado",IF(OR(P13="Reprovado",S13="Reprovado",V13="Reprovado"),"Reprovado","Pendente")) -> Aprovado | E13: 46162 | F13: Aprovação - Cancelamento de notas - PLANNE SOFTWARE LTDA-28.580.044/0001-57 |20697638 | G13: =RIGHT(Tabela1[[#This Row],[Assunto e-mail]],8) -> 20697638 | H13: OK | I13: Cancelamento de NF | J13: O cliente foi cobrado por um serviço que não chegou a ser implantado nem utilizado devido a falhas na integração e ausência de suporte. | K13: 6020.08 | L13: Emilly | N13: =IF(K13<10000,"Everton",IF(K13<=50000,"Everton + Tatebe","Everton + Tatebe + Calil")) -> Everton | O13: 46241 | P13: OK | R13: =IF(K13<10000,"N/A","") -> N/A | S13: =IF(K13<10000,"N/A","") -> N/A | T13: =IF(K13<10000,"N/A","-") -> N/A | U13: =IF(K13<=50000,"N/A","") -> N/A | V13: =IF(K13<=50000,"N/A","") -> N/A | W13: =IF(K13<=50000,"N/A","-") -> N/A
B14: =B13+1 -> 12 | C14: FALSE | D14: =IF(AND(P14="OK",OR(S14="OK",S14="N/A"),OR(V14="OK",V14="N/A")),"Aprovado",IF(OR(P14="Reprovado",S14="Reprovado",V14="Reprovado"),"Reprovado","Pendente")) -> Pendente | E14: 46232 | F14: Aprovação - Cancelamento de notas - AMERICANAS S.A - EM RECUPERACAO JUD 00.776.574/2019-92 - 23457203 | G14: =RIGHT(Tabela1[[#This Row],[Assunto e-mail]],8) -> 23457203 | H14: OK | I14: Cancelamento de NF | J14: Após a alteração de CNPJ, o cliente ficou impossibilitado de realizar os pagamentos, gerando as NFs em discussão para cancelamento até a conclusão do termo de cessão. | K14: 50579.53 | L14: Vanessa | N14: =IF(K14<10000,"Everton",IF(K14<=50000,"Everton + Tatebe","Everton + Tatebe + Calil")) -> Everton + Tatebe + Calil | O14: 46241 | P14: OK | R14: 46248 | S14: OK | T14: =IF(K14<10000,"N/A","-") -> - | U14: =IF(K14<=50000,"N/A","") | V14: =IF(K14<=50000,"N/A","") | W14: =IF(K14<=50000,"N/A","-") -> -
B15: =B14+1 -> 13 | C15: FALSE | D15: =IF(AND(P15="OK",OR(S15="OK",S15="N/A"),OR(V15="OK",V15="N/A")),"Aprovado",IF(OR(P15="Reprovado",S15="Reprovado",V15="Reprovado"),"Reprovado","Pendente")) -> Aprovado | E15: 46232 | F15: Aprovação - Cancelamento de notas - GOODSTORAGE HOLDING PARTICIPACOES -18.897.459/0001-03 | 25248269 | G15: =RIGHT(Tabela1[[#This Row],[Assunto e-mail]],8) -> 25248269 | H15: OK | I15: Cancelamento de NF | J15: Erro sistêmico | K15: 19897.96 | L15: Emilly | N15: =IF(K15<10000,"Everton",IF(K15<=50000,"Everton + Tatebe","Everton + Tatebe + Calil")) -> Everton + Tatebe | O15: 46241 | P15: OK | R15: 46255 | S15: OK | T15: =IF(K15<10000,"N/A","-") -> - | U15: =IF(K15<=50000,"N/A","") -> N/A | V15: =IF(K15<=50000,"N/A","") -> N/A | W15: =IF(K15<=50000,"N/A","-") -> N/A
B16: =B15+1 -> 14 | C16: FALSE | D16: =IF(AND(P16="OK",OR(S16="OK",S16="N/A"),OR(V16="OK",V16="N/A")),"Aprovado",IF(OR(P16="Reprovado",S16="Reprovado",V16="Reprovado"),"Reprovado","Pendente")) -> Aprovado | E16: 46234 | F16: Aprovação - Cancelamento de notas - GSE COMERCIO DE ROUPAS LTDA-22.675.768/0001-06 | 18822614 | G16: =RIGHT(Tabela1[[#This Row],[Assunto e-mail]],8) -> 18822614 | H16: OK | I16: Cancelamento de NF | J16: Solicitação de cancelamento integral não tratada corretamente, resultando em cobrança indevida após janeiro/2025. | K16: 12425.86 | L16: Emilly | N16: =IF(K16<10000,"Everton",IF(K16<=50000,"Everton + Tatebe","Everton + Tatebe + Calil")) -> Everton + Tatebe | O16: 46241 | P16: OK | R16: 46255 | S16: OK | T16: =IF(K16<10000,"N/A","-") -> - | U16: =IF(K16<=50000,"N/A","") -> N/A | V16: =IF(K16<=50000,"N/A","") -> N/A | W16: =IF(K16<=50000,"N/A","-") -> N/A
B17: =B16+1 -> 15 | C17: FALSE | D17: =IF(AND(P17="OK",OR(S17="OK",S17="N/A"),OR(V17="OK",V17="N/A")),"Aprovado",IF(OR(P17="Reprovado",S17="Reprovado",V17="Reprovado"),"Reprovado","Pendente")) -> Aprovado | E17: 46239 | F17: Aprovação - Cancelamento de notas-LUX INVEST CAPITAL LTDA- 34.383.831/0001-01 | 25264548- 25247817 | G17: =RIGHT(Tabela1[[#This Row],[Assunto e-mail]],8) -> 25247817 | H17: OK | I17: Cancelamento de NF | J17: Duplicidade contratual gerou faturamento indevido ao cliente. O contrato de produtos foi cancelado, mantendo apenas o Split ativo. Solicita-se o cancelamento de 9 NFs emitidas por erro comercial, incluindo a multa contratual. | K17: 45000 | L17: Emilly | N17: =IF(K17<10000,"Everton",IF(K17<=50000,"Everton + Tatebe","Everton + Tatebe + Calil")) -> Everton + Tatebe | O17: 46241 | P17: OK | R17: 46244 | S17: OK | T17: =IF(K17<10000,"N/A","-") -> - | U17: =IF(K17<=50000,"N/A","") -> N/A | V17: =IF(K17<=50000,"N/A","") -> N/A | W17: =IF(K17<=50000,"N/A","-") -> N/A
B18: =B17+1 -> 16 | C18: FALSE | D18: =IF(AND(P18="OK",OR(S18="OK",S18="N/A"),OR(V18="OK",V18="N/A")),"Aprovado",IF(OR(P18="Reprovado",S18="Reprovado",V18="Reprovado"),"Reprovado","Pendente")) -> Aprovado | E18: 46240 | F18: Aprovação - Cancelamento de notas -PHARMADELLE FORMULAS LTDA- 21.570.535/0001-78 | 19809905 | G18: 19809905 | H18: OK | I18: Cancelamento de NF | J18: O cliente solicitou o cancelamento em outubro/2023, entretanto, o processo não foi realizado. | K18: 3244.62 | L18: Emilly | N18: =IF(K18<10000,"Everton",IF(K18<=50000,"Everton + Tatebe","Everton + Tatebe + Calil")) -> Everton | O18: 46241 | P18: OK | R18: =IF(K18<10000,"N/A","") -> N/A | S18: =IF(K18<10000,"N/A","") -> N/A | T18: =IF(K18<10000,"N/A","-") -> N/A | U18: =IF(K18<=50000,"N/A","") -> N/A | V18: =IF(K18<=50000,"N/A","") -> N/A | W18: =IF(K18<=50000,"N/A","-") -> N/A
B19: =B18+1 -> 17 | C19: FALSE | D19: =IF(AND(P19="OK",OR(S19="OK",S19="N/A"),OR(V19="OK",V19="N/A")),"Aprovado",IF(OR(P19="Reprovado",S19="Reprovado",V19="Reprovado"),"Reprovado","Pendente")) -> Pendente | E19: 46241 | F19: Aprovação - Cancelamento de notas -MAGALUPAY INSTITUICAO DE PAGAMENTO- 13.884.775/0001-19 |25319444 | G19: =RIGHT(Tabela1[[#This Row],[Assunto e-mail]],8) -> 25319444 | H19: OK | I19: Cancelamento de NF | J19: Cancelamento solicitado em decorrência da ausência de solicitação tempestiva de cancelamento do produto, impossibilitando o cancelamento da NF dentro do prazo legal. | K19: 48773.21 | L19: Emilly | M19: Comercial | N19: =IF(K19<10000,"Everton",IF(K19<=50000,"Everton + Tatebe","Everton + Tatebe + Calil")) -> Everton + Tatebe | R19: 46248 | S19: OK | T19: =IF(K19<10000,"N/A","-") -> - | U19: =IF(K19<=50000,"N/A","") -> N/A | V19: =IF(K19<=50000,"N/A","") -> N/A | W19: =IF(K19<=50000,"N/A","-") -> N/A
B20: =B19+1 -> 18 | C20: FALSE | D20: =IF(AND(P20="OK",OR(S20="OK",S20="N/A"),OR(V20="OK",V20="N/A")),"Aprovado",IF(OR(P20="Reprovado",S20="Reprovado",V20="Reprovado"),"Reprovado","Pendente")) -> Aprovado | E20: 46239 | F20: Aprovação - Cancelamento de notas - VOLTATTO SUPRIMENTOS LTDA- 59.557.054/0001-03 | 24289294 | G20: =RIGHT(Tabela1[[#This Row],[Assunto e-mail]],8) -> 24289294 | I20: Cancelamento de NF | J20: Identificamos que, em decorrência de um erro sistêmico, a nota foi emitida em duplicidade. | K20: 248.98 | L20: Emilly | M20: Financeiro | N20: =IF(K20<10000,"Everton",IF(K20<=50000,"Everton + Tatebe","Everton + Tatebe + Calil")) -> Everton | O20: 46267 | P20: OK | R20: =IF(K20<10000,"N/A","") -> N/A | S20: =IF(K20<10000,"N/A","") -> N/A | T20: =IF(K20<10000,"N/A","-") -> N/A | U20: =IF(K20<=50000,"N/A","") -> N/A | V20: =IF(K20<=50000,"N/A","") -> N/A | W20: =IF(K20<=50000,"N/A","-") -> N/A
B21: =B20+1 -> 19 | C21: FALSE | D21: =IF(AND(P21="OK",OR(S21="OK",S21="N/A"),OR(V21="OK",V21="N/A")),"Aprovado",IF(OR(P21="Reprovado",S21="Reprovado",V21="Reprovado"),"Reprovado","Pendente")) -> Pendente | E21: 46247 | F21: Aprovação - Cancelamento de notas - GIORDANI TURISMO LTDA | Chamado: 2620110481154 | G21: 24912277 | H21: OK | I21: Cancelamento de NF | J21: A área de Cobrança identificou que a NF 0118088 foi emitida em duplicidade para o cliente GIORDANI TURISMO LTDA. Conforme validação realizada pela equipe responsável, a nota correta é a NF 0118002 | K21: 6266.85 | L21: Fabiana | M21: Financeiro | N21: =IF(K21<10000,"Everton",IF(K21<=50000,"Everton + Tatebe","Everton + Tatebe + Calil")) -> Everton | R21: 46248 | S21: OK | T21: =IF(K21<10000,"N/A","-") -> N/A | U21: =IF(K21<=50000,"N/A","") -> N/A | V21: =IF(K21<=50000,"N/A","") -> N/A | W21: =IF(K21<=50000,"N/A","-") -> N/A
B22: =B21+1 -> 20 | C22: FALSE | D22: =IF(AND(P22="OK",OR(S22="OK",S22="N/A"),OR(V22="OK",V22="N/A")),"Aprovado",IF(OR(P22="Reprovado",S22="Reprovado",V22="Reprovado"),"Reprovado","Pendente")) -> Pendente | E22: 46260 | F22: Cancelamento de NF COMERC FINANCIAL TRADING COMERCIALIZADORA DE ENERGIA LTDA | I22: Cancelamento de NF | J22: O cliente possui dois CNPJs, porém o contrato vigente está vinculado apenas a um deles. Por equívoco, a nota fiscal de setup foi emitida também para o CNPJ sem relação contratual ativa. | K22: 4236.49 | L22: Pamela | M22: Financeiro | N22: =IF(K22<10000,"Everton",IF(K22<=50000,"Everton + Tatebe","Everton + Tatebe + Calil")) -> Everton | R22: =IF(K22<10000,"N/A","") -> N/A | S22: =IF(K22<10000,"N/A","") -> N/A | T22: =IF(K22<10000,"N/A","-") -> N/A | U22: =IF(K22<=50000,"N/A","") -> N/A | V22: =IF(K22<=50000,"N/A","") -> N/A | W22: =IF(K22<=50000,"N/A","-") -> N/A
B23: =B22+1 -> 21 | C23: TRUE | D23: =IF(AND(P23="OK",OR(S23="OK",S23="N/A"),OR(V23="OK",V23="N/A")),"Aprovado",IF(OR(P23="Reprovado",S23="Reprovado",V23="Reprovado"),"Reprovado","Pendente")) -> Aprovado | E23: 46259 | F23: Aprovação - Cancelamento de notas - CENTRO CULTURAL AFRORIO - 11.697.918/0001-58 | 25578004 | G23: =RIGHT(Tabela1[[#This Row],[Assunto e-mail]],8) -> 25578004 | H23: OK | I23: Cancelamento de NF | J23: O contrato foi cancelado e houve aprovação formal da área comercial para o cancelamento integral das cobranças. O cadastro do cliente foi encerrado por decisão interna decorrente de apontamentos de risco identificados impossibilitando a continuidade da relação comercial. | K23: 18428.78 | L23: Amanda | M23: Comercial | N23: =IF(K23<10000,"Everton",IF(K23<=50000,"Everton + Tatebe","Everton + Tatebe + Calil")) -> Everton + Tatebe | O23: 46267 | P23: OK | R23: 46279 | S23: OK | T23: =IF(K23<10000,"N/A","-") -> - | U23: =IF(K23<=50000,"N/A","") -> N/A | V23: =IF(K23<=50000,"N/A","") -> N/A | W23: =IF(K23<=50000,"N/A","-") -> N/A
B24: =B23+1 -> 22 | C24: TRUE | D24: =IF(AND(P24="OK",OR(S24="OK",S24="N/A"),OR(V24="OK",V24="N/A")),"Aprovado",IF(OR(P24="Reprovado",S24="Reprovado",V24="Reprovado"),"Reprovado","Pendente")) -> Aprovado | E24: 46259 | F24: Aprovação - Cancelamento de notas - UNINTER EDUCACIONAL S/A - 02.261.854/0001-57 | 26341250 | G24: =RIGHT(Tabela1[[#This Row],[Assunto e-mail]],8) -> 26341250 | H24: OK | I24: Cancelamento de NF | J24: O cliente formalizou o pedido de cancelamento contratual em maio/2023, porém o processo foi concluído apenas em dezembro/2024. Em decorrência dessa falha operacional, permaneceram sendo geradas cobranças de mensalidade mínima. | K24: 21617.57 | L24: Amanda | M24: Comercial | N24: =IF(K24<10000,"Everton",IF(K24<=50000,"Everton + Tatebe","Everton + Tatebe + Calil")) -> Everton + Tatebe | O24: 46267 | P24: OK | R24: 46279 | S24: OK | T24: =IF(K24<10000,"N/A","-") -> - | U24: =IF(K24<=50000,"N/A","") -> N/A | V24: =IF(K24<=50000,"N/A","") -> N/A | W24: =IF(K24<=50000,"N/A","-") -> N/A
B25: =B24+1 -> 23 | C25: FALSE | D25: =IF(AND(P25="OK",OR(S25="OK",S25="N/A"),OR(V25="OK",V25="N/A")),"Aprovado",IF(OR(P25="Reprovado",S25="Reprovado",V25="Reprovado"),"Reprovado","Pendente")) -> Aprovado | E25: 46259 | F25: Aprovação - EDITORA SANAR S.A - 18.990.682/0001-92 - 18244519 | G25: =RIGHT(Tabela1[[#This Row],[Assunto e-mail]],8) -> 18244519 | H25: OK | I25: Cancelamento de NF | J25: O cliente solicitou o cancelamento do contrato na época, porém a solicitação não foi formalizada pelos gestores responsáveis. Em função dessa ausência de formalização, o contrato permaneceu ativo em nossos sistemas, ocasionando a continuidade da emissão das notas fiscais de forma indevida. | K25: 39695.55 | L25: Stephany | M25: Comercial | N25: =IF(K25<10000,"Everton",IF(K25<=50000,"Everton + Tatebe","Everton + Tatebe + Calil")) -> Everton + Tatebe | O25: 46267 | P25: OK | R25: 46279 | S25: OK | T25: =IF(K25<10000,"N/A","-") -> - | U25: =IF(K25<=50000,"N/A","") -> N/A | V25: =IF(K25<=50000,"N/A","") -> N/A | W25: =IF(K25<=50000,"N/A","-") -> N/A
B26: =B25+1 -> 24 | C26: TRUE | D26: =IF(AND(P26="OK",OR(S26="OK",S26="N/A"),OR(V26="OK",V26="N/A")),"Aprovado",IF(OR(P26="Reprovado",S26="Reprovado",V26="Reprovado"),"Reprovado","Pendente")) -> Aprovado | E26: 46261 | F26: Aprovação - Cancelamento de notas - INFRACOMMERCE SYNAPCOM COMERCI - 27.932.734/0001-65 | 26412747 | G26: =RIGHT(Tabela1[[#This Row],[Assunto e-mail]],8) -> 26412747 | H26: OK | I26: Cancelamento de NF | J26: As notas foram emitidas após a data de cancelamento do contrato (26/06/2023) devido à não conclusão do processo de cancelamento pelo time comercial à época. Dessa forma, houve faturamento indevido após o encerramento contratual. | K26: 44986.46 | L26: Amanda | M26: Comercial | N26: =IF(K26<10000,"Everton",IF(K26<=50000,"Everton + Tatebe","Everton + Tatebe + Calil")) -> Everton + Tatebe | O26: 46267 | P26: OK | R26: 46279 | S26: OK | T26: =IF(K26<10000,"N/A","-") -> - | U26: =IF(K26<=50000,"N/A","") -> N/A | V26: =IF(K26<=50000,"N/A","") -> N/A | W26: =IF(K26<=50000,"N/A","-") -> N/A
B27: =B26+1 -> 25 | C27: FALSE | D27: =IF(AND(P27="OK",OR(S27="OK",S27="N/A"),OR(V27="OK",V27="N/A")),"Aprovado",IF(OR(P27="Reprovado",S27="Reprovado",V27="Reprovado"),"Reprovado","Pendente")) -> Pendente | E27: 46262 | F27: Cancelamento de NFs DIAS FINANCE LTDA | H27: OK | I27: Cancelamento de NF | J27: A Nota Fiscal foi emitida para cobrança de multa contratual em decorrência do cancelamento do contrato do cliente LGS DIAS, realizado em 12/02/2026, quando ainda restavam 11 dias para o término do período contratual de 12 meses. Contudo, conforme alinhamento prévio entre o time Comercial e o cliente, foi acordado que o cancelamento ocorreria sem a aplicação de multa contratual. Dessa forma, a cobrança foi emitida indevidamente, não havendo obrigação de pagamento por parte do cliente. | K27: 91587.67 | L27: Pamela | M27: Comercial | N27: =IF(K27<10000,"Everton",IF(K27<=50000,"Everton + Tatebe","Everton + Tatebe + Calil")) -> Everton + Tatebe + Calil | R27: =IF(K27<10000,"N/A","") | S27: =IF(K27<10000,"N/A","") | T27: =IF(K27<10000,"N/A","-") -> - | U27: =IF(K27<=50000,"N/A","") | V27: =IF(K27<=50000,"N/A","") | W27: =IF(K27<=50000,"N/A","-") -> -
B28: =B27+1 -> 26 | C28: FALSE | D28: =IF(AND(P28="OK",OR(S28="OK",S28="N/A"),OR(V28="OK",V28="N/A")),"Aprovado",IF(OR(P28="Reprovado",S28="Reprovado",V28="Reprovado"),"Reprovado","Pendente")) -> Pendente | E28: 46259 | F28: Aprovação - Cancelamento de notas - N. R. BENNESBY COMERCIO DE UTE - 37.882.316/0001-64 | 26346273 | G28: =RIGHT(Tabela1[[#This Row],[Assunto e-mail]],8) -> 26346273 | H28: OK | I28: Cancelamento de NF | J28: Histórico de problemas operacionais reportados pelo cliente desde o início da relação comercial, incluindo intercorrências relacionadas à integração Shopify, antifraude e gestão de pedidos, que motivaram sucessivas solicitações de cancelamento e suspensão das cobranças. | K28: 121129.73 | L28: Amanda | M28: Operação | N28: =IF(K28<10000,"Everton",IF(K28<=50000,"Everton + Tatebe","Everton + Tatebe + Calil")) -> Everton + Tatebe + Calil | O28: 46267 | P28: OK | R28: 46279 | S28: OK | T28: =IF(K28<10000,"N/A","-") -> - | U28: =IF(K28<=50000,"N/A","") | V28: =IF(K28<=50000,"N/A","") | W28: =IF(K28<=50000,"N/A","-") -> -
B29: =B28+1 -> 27 | C29: FALSE | D29: =IF(AND(P29="OK",OR(S29="OK",S29="N/A"),OR(V29="OK",V29="N/A")),"Aprovado",IF(OR(P29="Reprovado",S29="Reprovado",V29="Reprovado"),"Reprovado","Pendente")) -> Pendente | F29: Aprovação - Cancelamento/baixa de notas ficais - GUEDES & PAIXAO LTDA 16928871003630 - 18604102 | G29: =RIGHT(Tabela1[[#This Row],[Assunto e-mail]],8) -> 18604102 | H29: ok | I29: Cancelamento de NF e Baixa | J29: Solicito, por gentileza, o seu DA, pois houve um atraso na implantação e, em tratativa realizada pelo time Comercial com o cliente, foi acordado o pagamento de 50% do valor devido. O time de Cobrança informou que o cliente efetuou o pagamento das notas fiscais contempladas no acordo. Dessa forma, precisamos realizar a baixa das notas fiscais relacionadas abaixo, que totalizam R$ 40.308,26. | K29: 40308.26 | L29: Stephany | M29: Operação | N29: =IF(K29<10000,"Everton",IF(K29<=50000,"Everton + Tatebe","Everton + Tatebe + Calil")) -> Everton + Tatebe | R29: =IF(K29<10000,"N/A","") | S29: =IF(K29<10000,"N/A","") | T29: =IF(K29<10000,"N/A","-") -> - | U29: =IF(K29<=50000,"N/A","") -> N/A | V29: =IF(K29<=50000,"N/A","") -> N/A | W29: =IF(K29<=50000,"N/A","-") -> N/A
B30: =B29+1 -> 28 | C30: FALSE | D30: =IF(AND(P30="OK",OR(S30="OK",S30="N/A"),OR(V30="OK",V30="N/A")),"Aprovado",IF(OR(P30="Reprovado",S30="Reprovado",V30="Reprovado"),"Reprovado","Pendente")) -> Pendente | F30: Aprovação - Cancelamento - FRUITFY INTERMEDIACOES E PAGAMENTOS 57315333000127 - 24820605 | G30: =RIGHT(Tabela1[[#This Row],[Assunto e-mail]],8) -> 24820605 | H30: ok | I30: Cancelamento de NF | J30: O cliente informou que enfrentou problemas durante a implementação da solução e declarou que não realizaria os pagamentos enquanto a implantação não estivesse concluída e aderente a tudo o que foi prometido e comercializado. Diante da negativa de pagamento e considerando o risco de ajuizamento, a Cielo optou pelo descredenciamento do cliente e pelo cancelamento das notas fiscais mencionadas. | K30: 1969.4 | L30: Stephany | M30: Operação | N30: =IF(K30<10000,"Everton",IF(K30<=50000,"Everton + Tatebe","Everton + Tatebe + Calil")) -> Everton | R30: =IF(K30<10000,"N/A","") -> N/A | S30: =IF(K30<10000,"N/A","") -> N/A | T30: =IF(K30<10000,"N/A","-") -> N/A | U30: =IF(K30<=50000,"N/A","") -> N/A | V30: =IF(K30<=50000,"N/A","") -> N/A | W30: =IF(K30<=50000,"N/A","-") -> N/A
B31: =B30+1 -> 29 | C31: FALSE | D31: =IF(AND(P31="OK",OR(S31="OK",S31="N/A"),OR(V31="OK",V31="N/A")),"Aprovado",IF(OR(P31="Reprovado",S31="Reprovado",V31="Reprovado"),"Reprovado","Pendente")) -> Pendente | F31: Aprovação - Cancelamento de notas fiscais - DENTAL S. SEBASTIAO LTDA - 09.228.091/0001-91 - 27115064 | G31: 27115064 | H31: ok | I31: Cancelamento de NF | J31: Aprovação - Cancelamento de notas fiscais - DENTAL S. SEBASTIAO LTDA - 09.228.091/0001-91 | K31: 5102.04 | L31: Stephany | N31: =IF(K31<10000,"Everton",IF(K31<=50000,"Everton + Tatebe","Everton + Tatebe + Calil")) -> Everton | R31: =IF(K31<10000,"N/A","") -> N/A | S31: =IF(K31<10000,"N/A","") -> N/A | T31: =IF(K31<10000,"N/A","-") -> N/A | U31: =IF(K31<=50000,"N/A","") -> N/A | V31: =IF(K31<=50000,"N/A","") -> N/A | W31: =IF(K31<=50000,"N/A","-") -> N/A
B32: =B31+1 -> 30 | C32: FALSE | D32: =IF(AND(P32="OK",OR(S32="OK",S32="N/A"),OR(V32="OK",V32="N/A")),"Aprovado",IF(OR(P32="Reprovado",S32="Reprovado",V32="Reprovado"),"Reprovado","Pendente")) -> Pendente | F32: Aprovação - Cancelamento de notas - VOLTBRAS ELETROPOSTOS AGENCIAMENTO LTDA - 32.150.686/0001-93 | 25704891 | G32: =RIGHT(Tabela1[[#This Row],[Assunto e-mail]],8) -> 25704891 | H32: OK | I32: Cancelamento de NF | J32: A integração da solução não foi concluída por questões técnicas, impossibilitando sua efetiva utilização pelo cliente. Além disso, após análise contratual, não foi identificada cláusula específica que estabeleça a obrigatoriedade do pagamento do SETUP nessa situação, motivo pelo qual o cliente formalizou contestação da cobrança por meio de notificação extrajudicial. | K32: 22974.01 | L32: Amanda | M32: Operação | N32: =IF(K32<10000,"Everton",IF(K32<=50000,"Everton + Tatebe","Everton + Tatebe + Calil")) -> Everton + Tatebe | R32: =IF(K32<10000,"N/A","") | S32: =IF(K32<10000,"N/A","") | T32: =IF(K32<10000,"N/A","-") -> - | U32: =IF(K32<=50000,"N/A","") -> N/A | V32: =IF(K32<=50000,"N/A","") -> N/A | W32: =IF(K32<=50000,"N/A","-") -> N/A
B33: =B32+1 -> 31 | C33: FALSE | D33: =IF(AND(P33="OK",OR(S33="OK",S33="N/A"),OR(V33="OK",V33="N/A")),"Aprovado",IF(OR(P33="Reprovado",S33="Reprovado",V33="Reprovado"),"Reprovado","Pendente")) -> Pendente | F33: Aprovação - Cancelamento de notas - JJGC. IND. E COM. MATERIAS DENTARIOS S/A - 00.489.050/0001-84 e 00.489.050/0002-65 | 26895066 | G33: =RIGHT(Tabela1[[#This Row],[Assunto e-mail]],8) -> 26895066 | H33: OK | I33: Cancelamento de NF | J33: O cliente formalizou a solicitação de cancelamento antes da primeira emissão de nota fiscal, para ambos os CNPJ's. Na época a gerente responsável (Isabella Lestingi), chegou a abrir no SF o cancelamento do contrato, mas não foi encaminhado para o financeiro. | K33: 63688.79 | L33: Amanda | M33: Comercial | N33: =IF(K33<10000,"Everton",IF(K33<=50000,"Everton + Tatebe","Everton + Tatebe + Calil")) -> Everton + Tatebe + Calil | R33: =IF(K32<10000,"N/A","") | S33: =IF(K32<10000,"N/A","") | T33: =IF(K33<10000,"N/A","-") -> - | U33: =IF(K33<=50000,"N/A","") | V33: =IF(K33<=50000,"N/A","") | W33: =IF(K33<=50000,"N/A","-") -> -
B34: =B33+1 -> 32 | C34: TRUE | D34: Aprovado | F34: Valores em aberto - Azzas 2154 | G34: 26988914 | H34: OK | I34: Cancelamento de NF | J34: A cliente informou que o pagamento individual das 78 notas gera um esforço operacional elevado, pois cada nota precisa estar vinculada a um boleto específico. Por esse motivo, solicitou a consolidação dos valores em 5 novos documentos fiscais e respectivos boletos. | K34: 389359.12 | L34: Vanessa | M34: Cobrança | N34: =IF(K34<10000,"Everton",IF(K34<=50000,"Everton + Tatebe","Everton + Tatebe + Calil")) -> Everton + Tatebe + Calil | T34: =IF(K34<10000,"N/A","-") -> - | U34: 46281 | V34: OK | W34: =IF(K34<=50000,"N/A","-") -> -
B35: =B34+1 -> 33 | C35: FALSE | D35: =IF(AND(P35="OK",OR(S35="OK",S35="N/A"),OR(V35="OK",V35="N/A")),"Aprovado",IF(OR(P35="Reprovado",S35="Reprovado",V35="Reprovado"),"Reprovado","Pendente")) -> Pendente | E35: 46286 | G35: 27241800 | I35: Cancelamento de NF | J35: Emissão em duplicidade | K35: 202.04 | L35: Amanda | M35: Financeiro | N35: =IF(K35<10000,"Everton",IF(K35<=50000,"Everton + Tatebe","Everton + Tatebe + Calil")) -> Everton | R35: =IF(K34<10000,"N/A","") | S35: =IF(K34<10000,"N/A","") | T35: =IF(K35<10000,"N/A","-") -> N/A | U35: =IF(K35<=50000,"N/A","") -> N/A | V35: =IF(K35<=50000,"N/A","") -> N/A | W35: =IF(K35<=50000,"N/A","-") -> N/A

Sheet Panorama
B1: Qtde. Total chamados Status | I1: Qtde. Total chamados por categoria | S1: Mês/Ano | T1: jul/2026
I2: Status | J2: PENDENTE | S2: Data de abertura | T2: (Tudo)
B4: #VALUE! | J4: Rótulos de Coluna | N4: PENDENTE | O4: FINALIZADO | P4: EM ANDAMENTO | Q4: A INICIAR | S4: Rótulos de Linha | T4: Contagem de Número do Chamado
J5: 2025 | K5: 2026 | L5: - | N5: =GETPIVOTDATA("Número do Chamado",$B$4,"Status","PENDENTE") -> #REF! | O5: =-GETPIVOTDATA("Número do Chamado",$B$4,"Status","FINALIZADO") -> #REF! | P5: =GETPIVOTDATA("Número do Chamado",$B$4,"Status","EM ANDAMENTO") -> #REF! | Q5: =SUM(N5:P5) -> #REF! | S5: Emilly Maria | T5: 20
S6: Fabiana Lisboa | T6: 12
S7: Pamela de Sá | T7: 24
S8: Stephany Lima | T8: 37
I9: Contagem de Número de protocolo | J9: 11 | K9: 84 | L9: 95 | S9: Vanessa Araujo | T9: 4
S10: Total Geral | T10: 97
B17: Qtde. Chamados por categoria x responsável
B18: Status | C18: PENDENTE
B19: Data de abertura | C19: (Vários itens)
B21: Rótulos de Linha | C21: Contagem Chamado
B22: Emilly Maria | C22: 13
B23: Fabiana Lisboa | C23: 10
B24: Pamela de Sá | C24: 23
B25: Stephany Lima | C25: 32
B26: Vanessa Araujo | C26: 6
B27: Total Geral | C27: 84
D45: Amanda verificar

Sheet Compilado chamados
B1: Atualizado em: | C1: 46290
L2: PENDENTE
L3: FINALIZADO
A4: Obs | B4: RESPONSÁVEL | C4: Classificação | D4: Número do Chamado | E4: Chamado Pai (clone) | F4: Número de protocolo | G4: Razão social | H4: CNPJ | I4: Causa raiz | J4: Observação/Ação | K4: Ofensor | L4: Status | M4: Prioridade | N4: Assunto | O4: Data de abertura | P4: Data da última modificação do chamado | Q4: Mês/Ano | R4: Proprietário do Chamado | S4: Email da Web | T4: Nome Fantasia | U4: Descrição | V4: Descrição detalhada | W4: Ref. | X4: Dt.Encerramento | Y4: Situação | Z4: Dias em Aberto | AA4: Aux_Ranking | AB4: Origem
B5: Stephany Lima | C5: =VLOOKUP(I:I,'Referencias '!H:I,2,0) -> Cobrança e Contestação | D5: 12555846 | E5: 0 | F5: 2512611298969 | G5: =T5 -> SUPERMERCADOS BOA LJ01 | I5: Ajuste de cobrança / faturamento | L5: FINALIZADO | M5: Médio | N5: Análise e Ajuste Condições | Boa Supermercado e Superpão | 1018 | 213299 | O5: 45783 | P5: 46003 | Q5: =TEXT(O5,"mmm/aaaa") -> mai/2025 | R5: Vanessa dos Santos Araujo | S5: support@braspag.zendesk.com | T5: SUPERMERCADOS BOA LJ01 | U5: ATENÇÃO: ESTE E-MAIL É DE UM REMETENTE EXTERNO À ORGANIZAÇÃO. Não clique em links ou abra anexos de remetentes desconhecidos ou suspeitos, ou sem validar com o remetente que o conteúdo é seguro. EM CASO DE DÚVIDAS, reporte este e-mail à equipe de Segurança da Informação, por meio do botão “DENUNCIAR PHISHING” em seu Outlook. No celular, você encontrará o botão clicando nos (...) no canto superior direito da mensagem, ao lado do nome do remetente. ##- Não escreva abaixo desta linha -## Você está registrado como CC nesta solicitação de suporte (213299). Responda este email para adicionar um comentário à solicitação. [https://braspag.zendesk.com/images/2016/default-avatar-80.png] Vanessa dos Santos Araujo (Cielo e-commerce) 6 de mai. de 2025, 11:16 BRT Observação privada Gabriela gabrielao@cielo.com.br * Empresa: Braspag * CNPJ: Gabriela * Causa raiz financeiro: Gabriela * Responsável pela demanda: Vanessa dos Santos Araujo [https://braspag.zendesk.com/images/201 | V5: Sem descrição | W5: =_xlfn.CONCAT(D5:E5) -> 125558460 | X5: 46245 | Y5: =IF(X5="","Aberto","Encerrado") -> Encerrado | Z5: =IF(OR(L5="PENDENTE",L5="EM ANDAMENTO",L5="PENDENTE APROVAÇÃO CANCELAMENTO NF"),TODAY()-O5,X5-O5) -> 462 | AA5: =IF(Y5="Aberto",Z5+ROW()/100000,"") | AB5: =IF(ISNUMBER(FIND("@cielo.com.br",S5)),"Interno","Externo") -> Externo
B6: Stephany Lima | C6: =VLOOKUP(I:I,'Referencias '!H:I,2,0) -> Cobrança e Contestação | D6: 13696702 | E6: 0 | F6: 2517719314576 | G6: =T6 -> www soares com br | I6: Ajuste de cobrança / faturamento | L6: FINALIZADO | M6: Médio | N6: 1018 Financeiro | Desejo falar com o setor financeiro | Fernanda Camarneira | fernanda.scamarneira@cielo.com.br | O6: 45834 | P6: 45947 | Q6: =TEXT(O6,"mmm/aaaa") -> jun/2025 | R6: Vanessa dos Santos Araujo | S6: fernanda.scamarneira@cielo.com.br | T6: www soares com br | U6: Olá, segue form enviado pela página de Ticket Braspag:<p><strong>Qual seu nome?:</strong> Fernanda Camarneira</p><p><strong>Endereço de e-mail:</strong> fernanda.scamarneira@cielo.com.br</p><p><strong>Telefone:</strong> (11) 94519-4834</p><p><strong>Assunto:</strong> Fast Solution - Reajuste Analista Advanced</p><p><strong>Sobre qual produto ou área deseja falar?:</strong> Financeiro</p><p><strong>Merchant ID/Estabelecimento Comercial (EC)*:</strong> 03.738.295/0001-96</p><p><strong>CNPJ:</strong> 03.738.295/0001-96</p><p><strong>Como podemos te ajudar?:</strong> Desejo falar com o setor financeiro</p><p><strong>Descrição do problema:</strong> o cliente FAST SOLUTION - 03.738.295/0001-96 realizou um upgrade de plano de antifraude Hierarquia para Advanced em 08/01/2025. Mas como já tinha um contrato com outra data de aniversário, já teve o reajuste aplicado agora em maio/2025 no analista advanced. Nos outros produtos está certo, precisamos aplicar. Mas no analista advanced precisamos r | V6: =IFERROR(_xlfn.TEXTBEFORE(_xlfn.TEXTAFTER(U6,"Descrição do problema:</strong"),"</p>"),_xlfn.TEXTAFTER(U6,"Descrição do problema:</strong")) -> > o cliente FAST SOLUTION - 03.738.295/0001-96 realizou um upgrade de plano de antifraude Hierarquia para Advanced em 08/01/2025. Mas como já tinha um contrato com outra data de aniversário, já teve o reajuste aplicado agora em maio/2025 no analista advanced. Nos outros produtos está certo, precisamos aplicar. Mas no analista advanced precisamos r | W6: =_xlfn.CONCAT(D6:E6) -> 136967020 | X6: 46245 | Y6: =IF(X6="","Aberto","Encerrado") -> Encerrado | Z6: =IF(OR(L6="PENDENTE",L6="EM ANDAMENTO",L6="PENDENTE APROVAÇÃO CANCELAMENTO NF"),TODAY()-O6,X6-O6) -> 411 | AA6: =IF(Y6="Aberto",Z6+ROW()/100000,"") | AB6: =IF(ISNUMBER(FIND("@cielo.com.br",S6)),"Interno","Externo") -> Interno
B7: Stephany Lima | C7: =VLOOKUP(I:I,'Referencias '!H:I,2,0) -> Cobrança e Contestação | D7: 13768449 | E7: 0 | F7: 2518211378652 | G7: =T7 -> CIELO SAINSTITUICAO DE PAGAMENTO | I7: Ajuste de cobrança / faturamento | L7: FINALIZADO | M7: Médio | N7: 1018 Financeiro | Desejo falar com o setor financeiro | Danilo | danilo_nunes@carrefour.com | O7: 45839 | P7: 45945 | Q7: =TEXT(O7,"mmm/aaaa") -> jul/2025 | R7: Vanessa dos Santos Araujo | S7: danilo_nunes@carrefour.com | T7: CIELO SAINSTITUICAO DE PAGAMENTO | U7: Olá, segue form enviado pela página de Ticket Braspag:<p><strong>Qual seu nome?:</strong> Danilo</p><p><strong>Endereço de e-mail:</strong> danilo_nunes@carrefour.com</p><p><strong>CNPJ:</strong> 45.543.915/0001-81</p><p><strong>Telefone:</strong> (11) 96363-2779</p><p><strong>Assunto:</strong> Carrefour | Faturamento Braspag Junho/2025</p><p><strong>Merchant ID/Estabelecimento Comercial (EC)*:</strong> 1bbe7159-6591-48b9-b101-639e81a33465</p><p><strong>Sobre qual produto ou área deseja falar?:</strong> Financeiro</p><p><strong>Como podemos te ajudar?:</strong> Desejo falar com o setor financeiro</p><p><strong>Data e hora do erro:</strong> 01-07-2025 11:22</p><p><strong>Descrição do problema:</strong> Olá, Para este faturamento de junho notificamos a necessidade da aplicação de um desconto referente ao retroativo do mês de abril R$37,55 Chamado de Abril : Antigo: 216094 Atual: 2512611299293 Faturamento Braspag | Abril 2024 | 1018 | ticket.id Por favor seguir com cancelamento da N | V7: =IFERROR(_xlfn.TEXTBEFORE(_xlfn.TEXTAFTER(U7,"Descrição do problema:</strong"),"</p>"),_xlfn.TEXTAFTER(U7,"Descrição do problema:</strong")) -> > Olá, Para este faturamento de junho notificamos a necessidade da aplicação de um desconto referente ao retroativo do mês de abril R$37,55 Chamado de Abril : Antigo: 216094 Atual: 2512611299293 Faturamento Braspag | Abril 2024 | 1018 | ticket.id Por favor seguir com cancelamento da N | W7: =_xlfn.CONCAT(D7:E7) -> 137684490 | X7: 46245 | Y7: =IF(X7="","Aberto","Encerrado") -> Encerrado | Z7: =IF(OR(L7="PENDENTE",L7="EM ANDAMENTO",L7="PENDENTE APROVAÇÃO CANCELAMENTO NF"),TODAY()-O7,X7-O7) -> 406 | AA7: =IF(Y7="Aberto",Z7+ROW()/100000,"") | AB7: =IF(ISNUMBER(FIND("@cielo.com.br",S7)),"Interno","Externo") -> Externo
B8: Vanessa Araujo | C8: =VLOOKUP(I:I,'Referencias '!H:I,2,0) -> Contratos, Comercial e Cadastro | D8: 13810507 | E8: 0 | F8: 2518315414788 | G8: =T8 -> CIELO SAINSTITUICAO DE PAGAMENTO | I8: Cancelamento de contrato | L8: FINALIZADO | M8: Médio | N8: 1003 Cancelamento de Contrato: Contábil Hub | O8: 45840 | P8: 46198 | Q8: =TEXT(O8,"mmm/aaaa") -> jul/2025 | R8: Emilly Maria Sousa Almeida | S8: joiceo@cielo.com.br | T8: CIELO SAINSTITUICAO DE PAGAMENTO | U8: -json-{"CancelamentoDeContratoId":"a0UNp00000YAtioMAD"} - CNPJ da Conta: 30.170.362/0001-91 - Razão Social: CB AFONSO SERVICOS ADMINISTRATIVOS LTDA - Transações Mensais: 200 - Data do Contrato: 17/11/2020 - Executivo: Caroline Matias da Costa - Motivo: Encerramento das Atividades - Justificativa: Encerramento das atividades. - Tipo: Total - Serviços: Cartão Protegido,Pagador - Observações: - Conta SF Id: 0014o00001k7wONAAY | V8: =TRIM(_xlfn.TEXTAFTER(U8,"-json-",-1)) -> {"CancelamentoDeContratoId":"a0UNp00000YAtioMAD"} - CNPJ da Conta: 30.170.362/0001-91 - Razão Social: CB AFONSO SERVICOS ADMINISTRATIVOS LTDA - Transações Mensais: 200 - Data do Contrato: 17/11/2020 - Executivo: Caroline Matias da Costa - Motivo: Encerramento das Atividades - Justificativa: Encerramento das atividades. - Tipo: Total - Serviços: Cartão Protegido,Pagador - Observações: - Conta SF Id: 0014o00001k7wONAAY | W8: =_xlfn.CONCAT(D8:E8) -> 138105070 | X8: 46227 | Y8: =IF(X8="","Aberto","Encerrado") -> Encerrado | Z8: =IF(OR(L8="PENDENTE",L8="EM ANDAMENTO",L8="PENDENTE APROVAÇÃO CANCELAMENTO NF"),TODAY()-O8,X8-O8) -> 387 | AA8: =IF(Y8="Aberto",Z8+ROW()/100000,"") | AB8: =IF(ISNUMBER(FIND("@cielo.com.br",S8)),"Interno","Externo") -> Interno
B9: Stephany Lima | C9: =VLOOKUP(I:I,'Referencias '!H:I,2,0) -> Cobrança e Contestação | D9: 15816740 | E9: 0 | F9: 2526910101742 | G9: =VLOOKUP(H:H,'Referencias '!B:C,2,0) -> HOSTGATOR BRASIL LTDA. | H9: =TRIM(_xlfn.TEXTBEFORE(_xlfn.TEXTAFTER(U9,"CNPJ/CPF:</strong>"),"</p>")) -> 15.754.475/0001-40 | I9: Dúvidas sobre cobrança | L9: FINALIZADO | M9: Médio | N9: 1011 Velocity Check | Estou em produção e tenho uma dúvida | Monica Murer | monica.murer@newfold.com | O9: 45926 | P9: 46028 | Q9: =TEXT(O9,"mmm/aaaa") -> set/2025 | R9: STEPHANY LIMA DE LISBOA | S9: monica.murer@newfold.com | T9: HOSTGATOR HOSP SITES | U9: Olá, segue formulário enviado para Cielo E-commerce:<p><strong>Qual seu nome?:</strong> Monica Murer</p><p><strong>Endereço de e-mail:</strong> monica.murer@newfold.com</p><p><strong>CNPJ/CPF:</strong> 15.754.475/0001-40</p><p><strong>Telefone:</strong> (48) 9943-0204</p><p><strong>Assunto:</strong> Velocity Check - Divergência nos valores faturados x Contrato.</p><p><strong>Merchant ID/Estabelecimento Comercial (EC):</strong> 1055024074</p><p><strong>Sobre qual produto ou área deseja falar?:</strong> Velocity Check</p><p><strong>Descrição do problema:</strong> Estou com uma dúvida sobre a cobrança do serviço de &quot;velocity check&quot; da Stelo, em nosso contrato, o valor desse serviço deveria ser fixo mensal, com reajuste apenas em novembro, usando a taxa do IPCA. No entanto, desde março, estamos notando valores diferentes e discrepantes nas cobranças. Segue abaixo valores reconhecidos na despesa de acordo com as NFs. Jan/Fev - R$466 / Mar - R$506 / Abr - R$763 / Mai - R$829 / Jun | V9: =IFERROR(_xlfn.TEXTBEFORE(_xlfn.TEXTAFTER(U9,"Descrição do problema:</strong"),"</p>"),_xlfn.TEXTAFTER(U9,"Descrição do problema:</strong")) -> > Estou com uma dúvida sobre a cobrança do serviço de &quot;velocity check&quot; da Stelo, em nosso contrato, o valor desse serviço deveria ser fixo mensal, com reajuste apenas em novembro, usando a taxa do IPCA. No entanto, desde março, estamos notando valores diferentes e discrepantes nas cobranças. Segue abaixo valores reconhecidos na despesa de acordo com as NFs. Jan/Fev - R$466 / Mar - R$506 / Abr - R$763 / Mai - R$829 / Jun | W9: =_xlfn.CONCAT(D9:E9) -> 158167400 | X9: 46245 | Y9: =IF(X9="","Aberto","Encerrado") -> Encerrado | Z9: =IF(OR(L9="PENDENTE",L9="EM ANDAMENTO",L9="PENDENTE APROVAÇÃO CANCELAMENTO NF"),TODAY()-O9,X9-O9) -> 319 | AA9: =IF(Y9="Aberto",Z9+ROW()/100000,"") | AB9: =IF(ISNUMBER(FIND("@cielo.com.br",S9)),"Interno","Externo") -> Externo
